Workbook

Sheet Tox Book
A1: INTOXICATE Status | B1: DOS | C1: Name | D1: DOB | E1: MRN | F1: Substance | G1: toxIC ID | H1: Pt code | I1: ICD-10 | J1: OUD supplemental | K1: RA | L1: Notes | M1: Redcap | N1: Smartsheet
A2: added to INTOXICATE tab | B2: 44954 | C2: Lauren Holly | D2: 35068 | E2: 1401090590 | F2: Ethanol | G2: 131515-1 | H2: WCM2023-1 | I2: F10.10? | K2: SR
A3: added to INTOXICATE tab | B3: 44958 | C3: Avery Grace | D3: 32649 | E3: 1001720769 | F3: Ethanol | G3: 131515-2 | H3: WCM2023-2 | I3: R41.82 | K3: SR
B4: 44958 | C4: Zaki Lantos | D4: 41278 | E4: 1011053895 | F4: Cannabis | G4: 131515-3 | H4: WCM2023-3 | I4: F19.920 | K4: SR
A5: added to INTOXICATE tab | B5: 44959 | C5: Jose Guszman | D5: 38504 | E5: 1401096023 | F5: Ethanol | G5: 131515-4 | H5: WCM2023-4 | I5: F10.10 | K5: SR
A6: added to INTOXICATE tab | B6: 44962 | C6: Bertha Niola | D6: 31656 | E6: 1006629455 | F6: CO intox | G6: 131515-6 | H6: WCM2023-6 | I6: T58.91XA | K6: SR | L6: Progress note only
A7: added to INTOXICATE tab | B7: 44962 | C7: Anna Dalbello | D7: 12547 | E7: 1010033242 | F7: AMS | G7: 131515-7 | H7: WCM2023-7 | K7: SR | L7: Consult note
A8: added to INTOXICATE tab | B8: 44988 | C8: Eliot Pandev | D8: 44372 | E8: 1400361697 | F8: possible APAP | G8: 131515-5 | H8: WCM2023-5 | K8: CH
A9: added to INTOXICATE tab | B9: 44990 | C9: Carol Toscano | D9: 23473 | E9: 1001694549 | F9: Bupropion | G9: 131515-8 | H9: WCM2023-8 | K9: CH
A10: added to INTOXICATE tab | B10: 45003 | C10: Yvelisse Severino | D10: 20739 | E10: 1006139627 | F10: Household - cleaning product | G10: 131515-9 | H10: WCM2023-9 | K10: CH
A11: added to INTOXICATE tab | B11: 45000 | C11: Madeline Cheung | D11: 39724 | E11: 1009487000 | F11: Escitalopram | G11: 131515-10 | H11: WCM2023-10 | K11: CH
A12: Excluded | B12: 45011 | C12: Gabriel Alhaddad | D12: 40406 | E12: 1401099922 | F12: none identified | G12: 131515-11 | H12: WCM2023-11 | K12: CH
A13: Excluded | B13: 45004 | C13: Moshe Blau | D13: 38014 | E13: 1010178079 | F13: Lithium/s. cannab | G13: 131515-12 | H13: WCM2023-12 | K13: SR
A14: Excluded | B14: 45010 | C14: Albert Hartell | D14: 39197 | E14: 1400775825 | F14: Polysubstance | G14: 131515-13 | H14: WCM2023-13 | K14: SR
A15: added to INTOXICATE tab | B15: 45010 | C15: Sara Jones | D15: 31154 | E15: 1401159022 | F15: EtOH | G15: 131515-14 | H15: WCM2023-14 | K15: SR
A16: Excluded | B16: 45010 | C16: Katharine Weber | D16: 36995 | E16: 1008398675 | G16: 131515-15 | H16: WCM2023-15 | K16: SR
A17: added to INTOXICATE tab | B17: 44995 | C17: Angelo Woodley Sinclair | D17: 24330 | E17: 1401141829 | F17: Fluoxetine, lamictal, alprazolam | G17: 131515-16 | H17: WCM2023-16 | I17: T50.902A | K17: CH
A18: Excluded | B18: 45010 | C18: George Friedlander | D18: 35373 | E18: 1003874435 | G18: 131515-17 | H18: WCM2023-17 | I18: R09.89; K50.90 | K18: SR
A19: added to INTOXICATE tab | B19: 45011 | C19: Alexander Rando | D19: 36996 | E19: 1008108363 | F19: EtOH | G19: 131515-18 | H19: WCM2023-18 | I19: R09.89 | K19: SR
A20: added to INTOXICATE tab | B20: 45019 | C20: Peyson Sam | D20: 41285 | E20: 1101578680 | F20: unknown substance (drugs in home include acetaminophen, ibuprofen, or lisinopril) | G20: 131515-19 | H20: WCM2023-19 | K20: CH | N20: not on Smartsheet
A21: added to INTOXICATE tab | B21: 45020 | C21: Naheed Masroor | D21: 22077 | E21: 1000053365 | F21: Lorazepam | G21: 131515-20 | H21: WCM2023-20 | K21: CH | N21: both
A22: added to INTOXICATE tab | B22: 45011 | C22: Diane Pedrez | D22: 24743 | E22: 1100404076 | F22: Gabapentin, Fioricet | G22: 131515-21 | H22: WCM2023-21 | I22: R41.82 | K22: SR
A23: added to INTOXICATE tab | B23: 45011 | C23: Annie Lai | D23: 29427 | E23: 1007809059 | F23: Bupropion | G23: 131515-22 | H23: WCM2023-22 | I23: V15.89 V72.6 G40 | K23: SR
A24: added to INTOXICATE tab | B24: 45011 | C24: Theo Rosenthal | D24: 26526 | E24: 1011109895 | F24: Tylenol overdose | G24: 131515-23 | H24: WCM2023-23 | I24: T14.91XA T39.1X1A | K24: SR
A25: added to INTOXICATE tab | B25: 45004 | C25: Richard Bennett | D25: 26635 | E25: 1102644291 | F25: OD levatiracetam | G25: 131515-24 | H25: WCM2023-24 | I25: T50. 902A | K25: SR
A26: Excluded | B26: 45014 | C26: Nic Platt | D26: 13219 | E26: 1100515863 | F26: Verapimil | G26: 131515-25 | H26: WCM2023-25 | I26: R09.89 R00.1 | K26: SR | L26: calcium channel toxicity
A27: Excluded | B27: 45014 | C27: Elizabeth Molina | D27: 42816 | E27: 1401164435 | F27: OD Risperidone | G27: 131515-26 | H27: WCM2023-26 | I27: T43.591A | K27: SR
A28: Excluded | B28: 45023 | C28: Victor Solis | D28: 36182 | E28: 1006210420 | F28: N/A | G28: N/A | H28: N/A | I28: N/A | K28: CH | L28: tox consulted for possible CO exposure but it was ruled out. Patient did have EtOH intoxication but unrelated to presentation. | M28: No | N28: both
A29: Excluded | B29: 45024 | C29: Julissa Rivera | D29: 26514 | E29: 1007851286 | H29: not added yet | K29: CH | L29: not in redcap - question on whether this is considered a tox exposure | N29: both
A30: added to INTOXICATE tab | B30: 45026 | C30: Alexander Rutherfoord | D30: 33457 | E30: 1400587005 | F30: MDMA, THC, ketamine | G30: 131515-27 | H30: WCM2023-27 | K30: CH | N30: both | O30: Dr. Rao "progress note" Inpatient consult to toxicology CON67 in referrals Inpatient consult to toxicology in orders
A31: Excluded | B31: 45032 | C31: Violet Warsavsky | D31: 44216 | E31: 1400182363 | F31: estradiol pills | G31: 131515-28 | H31: WCM2023-28 | K31: CH | N31: both
A32: Excluded | B32: 45032 | C32: Gustav Seliger | D32: 13727 | E32: 1004568326 | H32: not added yet | K32: CH | L32: consult for possible benzo OD, however, progress note on 4/17/2023 seems to rule out this was the cause of symptoms "Initially obtundation thought to be 2/2 poly-pharmacy, although lack of improvement I/s/o absence of severe renal and hepatic dysfunction make such hypothesis less likely. I spoke at length to the patient's wife and son today. Neither has seen evidence of empty pill bottles or rummaging through the medicine cabinet that would suggest an intentional overdose." | N32: both
A33: Excluded | B33: 45032 | C33: Amere Mercado | D33: 37438 | E33: 1006210897 | F33: capsaicin | G33: 131515-29 | H33: WCM2023-29 | K33: CH | N33: not on Smartsheet
A34: Excluded | B34: 45035 | C34: James Clark | D34: 16154 | E34: 1008799858 | F34: AMS | K34: SR | L34: pt presented for mania and dillirium. chronic behavioral change with manic, impulsive behavior, paranoia, and agitation. He underwent extensive medical workup unrevealing of reversible cause. Neurology team suspects neurodegenerative disorder based on history and brain volume loss. Per psychiatry, his presentation is likely a combination of neurocognitive disorder in the setting of possible longstanding hypomania. UA, RVP, ESR, CRP, Procal, TSH/FT4, folate, B12, ammonia, HIV, RPR, heavy metal panel, and thallium level were unrevealing. benzo positive. pt received IV Thiamine supplementation | M34: NO | N34: both
A35: added to INTOXICATE tab | B35: 45035 | C35: Caroline Ritter | D35: 27789 | E35: 1006702172 | F35: AMS, toxic alcohol unspecified | G35: 131515-31 | H35: 131515-31 | K35: SR | N35: both
B36: 45036 | C36: Caroline Ritter | D36: 27789 | E36: 1006702172
B37: 45036 | C37: Zunilda Estevez | D37: 19953 | E37: 1000011302 | F37: Septic shock with multisystem organ failure NSTEMI Chronic opioid use disorder | N37: not on Smartsheet
B38: 45036 | C38: Emilie Laverdiere | D38: 43547 | E38: 1201281826 | N38: not on Smartsheet
A39: Excluded | B39: 45036 | C39: Owen Miguel Blanco-Kenny | D39: 44269 | E39: 1400242416 | F39: N/A | G39: N/A | H39: N/A | I39: N/A | K39: CH | L39: tox cause r/o | M39: No | N39: not on Smartsheet
A40: added to INTOXICATE tab | B40: 45037 | C40: Michael Maccini | D40: 22419 | E40: 1007329807 | F40: EtOH, Venlafaxine | G40: 131515-30 | H40: WCM2023-30 | K40: SR | N40: not on Smartsheet
...

Sheet INTOXICATE
A1: ToxIC ID | B1: Gender | C1: Exposure Category | D1: Age | E1: Pulse | F1: SBP | G1: GCS | H1: Respiratory Insufficiency | I1: Cirrhosis | J1: Dysrhythmia | K1: Secondary Reason for ICU Admission | L1: INTOXICATE SCORE | M1: Optimized Predicted Disposition | N1: Predicted Disposition | O1: Predicted Ignore Sinus | P1: Predicted Ignore Sinus < 140 | Q1: Actual Disposition | R1: Substance of Exposure | S1: Longer Term Complication | T1: 30-Day Mortality | U1: In Retrospect Required ICU | V1: Additional Disposition Notes | W1: Confirmed Exposure | X1: Primary Etiology Tox | Y1: Categorial Values
A2: 131515-97 | B2: F | C2: Street Drugs | D2: 1 | E2: 114 | F2: 120 | G2: 15 | H2: No | I2: No | J2: No | K2: No | L2: 5 | M2: =IF($L2>17,"ICU","GMF") -> GMF | N2: GMF | Q2: Discharge | R2: possbile adderall 10 mg | S2: No | T2: No | U2: No | V2: Sinus tachycardia infaltes INTOXICATE's recommendations, drug test was cancelled due to "unable" No symptoms thus no primary etiology tox (only reason for admission was tox though) | W2: Unconfirmed | X2: Yes | Y2: Yes | AA2: Exposure Values | AB2: Confirmed Values
A3: 131515-5 | B3: F | C3: Analgesic | D3: 2 | E3: 116 | F3: NaN | G3: 15 | H3: No | I3: No | J3: No | K3: No | M3: =IF($L3>17,"ICU","GMF") -> GMF | Q3: Discharge | R3: Tylenol | S3: No | T3: No | W3: Confirmed -Yes | X3: Yes | Y3: No | AA3: Alcohol | AB3: Confirmed -Yes
A4: 131515-95 | B4: M | C4: Sedatives | D4: 2 | E4: 112 | F4: NaN | G4: 15 | H4: No | I4: No | J4: No | K4: No | M4: =IF($L4>17,"ICU","GMF") -> GMF | Q4: Discharge | R4: possible 10 mg THC gummy | S4: No | T4: No | U4: No | V4: clinical signs of intox pediatric THC intox, Drug test cancelled ("lab auto cancel no specimen received") | W4: Unconfirmed | X4: Yes | AA4: Analgesic | AB4: Confirmed- No
A5: 131515-59 | B5: F | C5: Antidepressants | D5: 3 | E5: 102 | F5: 92 | G5: 15 | H5: No | I5: No | J5: No | K5: No | L5: 7 | M5: =IF($L5>17,"ICU","GMF") -> GMF | N5: ICU | Q5: Discharge | R5: 30mg mirtazapine | S5: No | T5: No | U5: No | V5: Sinus tachycardia infaltes INTOXICATE's recommendations | W5: Unconfirmed | X5: Yes | AA5: Antidepressants | AB5: Unconfirmed
B6: M | C6: CO, As, CN | D6: 7 | E6: 127 | F6: 93 | G6: 15 | H6: Yes | I6: No | J6: Yes | K6: No | L6: 15 | M6: =IF($L6>17,"ICU","GMF") -> GMF | N6: ICU | Q6: Discharge | R6: CO | S6: No | T6: No | U6: No | W6: Confirmed -Yes | X6: Yes | AA6: Street Drugs | AB6: N/A - Withdrawal
B7: F | C7: CO, As, CN | D7: 8 | E7: 117 | F7: 112 | G7: 15 | H7: Yes | I7: No | J7: Yes | K7: No | L7: 12 | M7: =IF($L7>17,"ICU","GMF") -> GMF | N7: ICU | Q7: Discharge | R7: CO | S7: No | T7: No | U7: No | W7: Confirmed -Yes | X7: Yes | AA7: Sedatives
B8: M | C8: Antidepressants | D8: 10 | E8: 100 | F8: 114 | G8: 15 | H8: No | I8: No | J8: No | K8: No | L8: 4 | M8: =IF($L8>17,"ICU","GMF") -> GMF | N8: GMF | Q8: Discharge | R8: 225 mg zoloft | S8: No | T8: No | U8: No | W8: Unconfirmed | X8: Yes | AA8: CO, As, CN
A9: 131515-19 | B9: F | C9: Unknown | D9: 10 | E9: 120 | F9: 105 | G9: 15 | H9: No | I9: No | J9: Yes | K9: No | L9: 13 | M9: =IF($L9>17,"ICU","GMF") -> GMF | N9: ICU | Q9: Discharge | R9: took various pills from a cabinet with multiple medications | S9: No | T9: No | U9: No | V9: EKG with sinius tachycardia | W9: Unconfirmed | X9: Yes | AA9: Unknown
A10: 131515-79 | B10: F | C10: Analgesic | D10: 12 | E10: 81 | F10: 106 | G10: 15 | H10: No | I10: No | J10: No | K10: No | L10: 4 | M10: =IF($L10>17,"ICU","GMF") -> GMF | N10: GMF | Q10: Discharge | R10: Percocet | S10: No | T10: No | U10: No | W10: Confirmed- No | X10: Yes | AA10: Combination
A11: 131515-88 | B11: F | C11: Combination | D11: 12 | E11: 91 | F11: 116 | G11: 15 | H11: No | I11: No | J11: No | K11: No | L11: 3 | M11: =IF($L11>17,"ICU","GMF") -> GMF | N11: GMF | Q11: Discharge | R11: oxycodone and ibuprofen | S11: No | T11: No | U11: No | V11: Transfer to psych, no specimen for drug test received | W11: Unconfirmed | X11: Yes
B12: F | C12: Unknown | D12: 12 | E12: 97 | F12: 127 | G12: 14 | H12: No | I12: No | J12: No | K12: No | L12: 5 | M12: =IF($L12>17,"ICU","GMF") -> GMF | N12: GMF | Q12: Discharge | R12: inahled powdered glue from sticker collection; tox also + for oxycodone & opiates | S12: No | T12: No | U12: No | V12: Transfer to psych | W12: Confirmed -Yes | X12: Yes
B13: NB | C13: Antidepressants | D13: 13 | E13: 114 | F13: 119 | G13: 15 | H13: No | I13: No | J13: Yes | K13: No | L13: 10 | M13: =IF($L13>17,"ICU","GMF") -> GMF | N13: ICU | Q13: Discharge | R13: zoloft | S13: No | T13: No | U13: No | V13: Transfer to psych | W13: Unconfirmed | X13: Yes
B14: F | C14: Unknown | D14: 13 | E14: 101 | F14: 104 | G14: 15 | H14: No | I14: No | J14: Yes | K14: No | L14: 12 | M14: =IF($L14>17,"ICU","GMF") -> GMF | N14: ICU | Q14: Discharge | R14: ingestion of two home cleaning solutions (Shout & Cascade) | S14: No | T14: No | U14: No | V14: Transfer to psych | W14: Unconfirmed | X14: Yes
A15: 131515-10 | B15: F | C15: Antidepressants | D15: 14 | E15: 97 | F15: 116 | G15: 15 | H15: No | I15: No | J15: No | K15: No | L15: 4 | M15: =IF($L15>17,"ICU","GMF") -> GMF | N15: GMF | Q15: Discharge | S15: No | T15: No | W15: Unconfirmed | X15: Yes
A16: 131515-60 | B16: M | C16: Analgesic | D16: 14 | E16: 101 | F16: 107 | G16: 15 | H16: No | I16: No | J16: Yes | K16: No | L16: 11 | M16: =IF($L16>17,"ICU","GMF") -> GMF | N16: ICU | Q16: Discharge | R16: analgesic (dominant ingestion) - 2,000mg of tylenol, 2200mg of ibuprofen, 1mg risperdol, 10mg of zyrtec and 1 cup of wine | S16: No | T16: No | U16: No | W16: Confirmed -Yes | X16: Yes
B17: F | C17: Analgesic | D17: 14 | E17: 106 | F17: 131 | G17: 15 | H17: No | I17: No | J17: Yes | K17: No | L17: 9 | M17: =IF($L17>17,"ICU","GMF") -> GMF | N17: ICU | Q17: Discharge | R17: ibuprofen | S17: No | T17: No | U17: No | V17: Transfer to psych | W17: Unconfirmed | X17: Yes | AA17: Actual | AB17: ALL | AD17: PEDS | AF17: ADULT
A18: 131515-69 | B18: M | C18: Analgesic | D18: 15 | E18: 82 | F18: 118 | G18: 15 | H18: No | I18: No | J18: No | K18: No | L18: 3 | M18: =IF($L18>17,"ICU","GMF") -> GMF | N18: GMF | Q18: Discharge | R18: Tylenol | S18: No | T18: No | U18: No | W18: Confirmed -Yes | X18: Yes | AA18: ICU | AB18: =COUNTIFS($D$2:$D$115,">="&12,$Q$2:$Q$115,$AA18) -> 20 | AC18: =ROUND(100*AB18/AB$21,0) -> 19 | AD18: =COUNTIFS($D$2:$D$115,">="&12,$Q2:$Q115,$AA18, $D$2:$D$115,"<"&18) -> 4 | AE18: =ROUND(100*AD18/AD$21,0) -> 17 | AF18: =COUNTIFS($D$2:$D$115,">="& 18,$Q2:$Q115,$AA18) -> 16 | AG18: =ROUND(100*AF18/AF$21,0) -> 21
A19: 131515-71 | B19: M | C19: Street Drugs | D19: 15 | E19: 97 | F19: 110 | G19: 15 | H19: No | I19: No | J19: No | K19: No | L19: 5 | M19: =IF($L19>17,"ICU","GMF") -> GMF | N19: GMF | Q19: Discharge | R19: THC Gummy | S19: No | T19: No | U19: No | W19: Confirmed -Yes | X19: Yes | AA19: GMF | AB19: =COUNTIFS($D$2:$D$115,">="&12,$Q$2:$Q$115,$AA19) -> 16 | AC19: =ROUND(100*AB19/AB$21,0) -> 16 | AD19: =COUNTIFS($D$2:$D$115,">="&12,$Q3:$Q116,$AA19, $D$2:$D$115,"<"&18) -> 2 | AE19: =ROUND(100*AD19/AD$21,0) -> 8 | AF19: =COUNTIFS($D$2:$D$115,">="& 18,$Q3:$Q116,$AA19) -> 14 | AG19: =ROUND(100*AF19/AF$21,0) -> 18
B20: F | C20: Street Drugs | D20: 15 | E20: 79 | F20: 97 | G20: 15 | H20: No | I20: No | J20: No | K20: No | L20: 6 | M20: =IF($L20>17,"ICU","GMF") -> GMF | N20: GMF | Q20: Discharge | R20: 2mg xanax, "snorted few lines of ketamine and oxycodone", 2 small crystals of molly | S20: No | T20: No | U20: No | V20: Transfer to psych | W20: Confirmed -Yes | X20: Yes | AA20: Discharge | AB20: =COUNTIFS($D$2:$D$115,">="&12,$Q$2:$Q$115,$AA20) -> 67 | AC20: =ROUND(100*AB20/AB$21,0) -> 65 | AD20: =COUNTIFS($D$2:$D$115,">="&12,$Q4:$Q117,$AA20, $D$2:$D$115,"<"&18) -> 18 | AE20: =ROUND(100*AD20/AD$21,0) -> 75 | AF20: =COUNTIFS($D$2:$D$115,">="& 18,$Q4:$Q117,$AA20) -> 47 | AG20: =ROUND(100*AF20/AF$21,0) -> 61
A21: 131515-80 | B21: M | C21: Street Drugs | D21: 16 | E21: 73 | F21: 89 | G21: 14 | H21: No | I21: No | J21: No | K21: No | L21: 5 | M21: =IF($L21>17,"ICU","GMF") -> GMF | N21: GMF | Q21: Discharge | R21: THC Gummy | S21: No | T21: No | U21: No | W21: Confirmed -Yes | X21: Yes | AB21: =SUM(AB$18:AB$20) -> 103 | AD21: =SUM(AD$18:AD$20) -> 24 | AF21: =SUM(AF$18:AF$20) -> 77
B22: F | C22: Unknown | D22: 16 | E22: 94 | F22: 119 | G22: 15 | H22: No | I22: No | J22: No | K22: No | L22: 5 | M22: =IF($L22>17,"ICU","GMF") -> GMF | N22: GMF | Q22: Discharge | R22: ethanol and unknown pill from stranger | S22: No | T22: No | U22: No | W22: Confirmed -Yes | X22: Yes
A23: 131515-55 | B23: F | C23: Street Drugs | D23: 16 | E23: 115 | F23: 105 | G23: 15 | H23: No | I23: No | J23: Yes | K23: No | L23: 12 | M23: =IF($L23>17,"ICU","GMF") -> GMF | N23: ICU | Q23: Discharge | R23: 6 CBD (200mg total) gummies | S23: No | T23: No | U23: No | V23: Sinus tachycardia infaltes INTOXICATE's recommendations | W23: Confirmed -Yes | X23: Yes | AA23: Total | AB23: =COUNTIF($D$2:$D$155,">="&12) -> 103
B24: M | C24: Antidepressants | D24: 16 | E24: 120 | F24: 119 | G24: 15 | H24: No | I24: No | J24: Yes | K24: No | L24: 10 | M24: =IF($L24>17,"ICU","GMF") -> GMF | N24: ICU | Q24: Discharge | R24: clomipramine | S24: No | T24: No | U24: No | W24: Confirmed -Yes | X24: Yes
A25: 131515-73 | B25: F | C25: Antidepressants | D25: 17 | E25: 134 | F25: 101 | G25: 15 | H25: No | I25: No | J25: Yes | K25: No | L25: 11 | M25: =IF($L25>17,"ICU","GMF") -> GMF | N25: ICU | Q25: Discharge | R25: Trazodone | S25: No | T25: No | U25: No | V25: Transfer to psych | W25: Confirmed -Yes | X25: Yes
A26: 131515-75 | B26: F | C26: Antidepressants | D26: 17 | E26: 109 | F26: 127 | G26: 15 | H26: No | I26: No | J26: Yes | K26: No | L26: 9 | M26: =IF($L26>17,"ICU","GMF") -> GMF | N26: ICU | Q26: Discharge | R26: Prozac | S26: No | T26: No | U26: No | V26: Transfer to psych | W26: Unconfirmed | X26: Yes
B27: M | C27: Unknown | D27: 17 | E27: 115 | F27: 99 | G27: 15 | H27: No | I27: No | J27: Yes | K27: No | L27: 15 | M27: =IF($L27>17,"ICU","GMF") -> GMF | N27: ICU | Q27: Discharge | R27: wild mushroom ingestion | S27: No | T27: No | U27: No | W27: Unconfirmed | X27: Yes | Y27: Agreement
A28: 131515-70 | B28: F | C28: Analgesic | D28: 18 | E28: 87 | F28: 125 | G28: 15 | H28: No | I28: No | J28: No | K28: No | L28: 3 | M28: =IF($L28>17,"ICU","GMF") -> GMF | N28: GMF | Q28: Discharge | R28: Motrin | S28: No | T28: No | U28: No | V28: Transfer to psych | W28: Confirmed -Yes | X28: Yes | AB28: MD
B29: F | C29: CO, As, CN | D29: 18 | E29: 74 | F29: 115 | G29: 15 | H29: Yes | I29: No | J29: No | K29: No | L29: 3 | M29: =IF($L29>17,"ICU","GMF") -> GMF | N29: GMF | Q29: Discharge | R29: CO | S29: No | T29: No | U29: Policy | V29: CO poisoning | W29: Confirmed -Yes | X29: yes | AB29: ICU | AC29: Not
A30: 131515-51 | B30: M | C30: Street Drugs | D30: 18 | E30: 55 | F30: 118 | G30: 15 | H30: No | I30: No | J30: Yes | K30: No | L30: 7 | M30: =IF($L30>17,"ICU","GMF") -> GMF | N30: ICU | Q30: Discharge | S30: No | T30: No | U30: No | V30: Sinus tachycardia infaltes INTOXICATE's recommendations | W30: Confirmed- No | X30: No | Y30: Original threshold | Z30: Algo | AA30: ICU | AB30: =COUNTIFS($Q$2:$Q$120,"ICU",$N$2:$N$120,"ICU",$D$2:$D$120,">"&11) -> 13 | AC30: =COUNTIFS($Q$2:$Q$120,"<>ICU",$N$2:$N$120,"ICU",$D$2:$D$120,">"&11) -> 48
A31: 131515-57 | B31: F | C31: Antidepressants | D31: 19 | E31: 90 | F31: 125 | G31: 15 | H31: No | I31: No | J31: No | K31: No | L31: 2 | M31: =IF($L31>17,"ICU","GMF") -> GMF | N31: GMF | Q31: Discharge | S31: No | T31: No | U31: No | W31: Confirmed- No | X31: Yes | AA31: Not | AB31: =COUNTIFS($Q$2:$Q$120,"ICU",$N$2:$N$120,"<>ICU",$D$2:$D$120,">"&11) -> 7 | AC31: =COUNTIFS($Q$2:$Q$120,"<>ICU",$N$2:$N$120,"<>ICU",$D$2:$D$120,">"&11) -> 35
A32: 131515-62 | B32: F | C32: Alcohol | D32: 20 | E32: 110 | F32: 128 | G32: 15 | H32: No | I32: No | J32: Yes | K32: No | L32: 4 | M32: =IF($L32>17,"ICU","GMF") -> GMF | N32: GMF | Q32: Discharge | S32: No | T32: No | U32: No | W32: Unconfirmed | X32: Yes | AB32: SUM | AC32: =SUM(AB30:AC31) -> 103 | AE32: Kappa
A33: 131515-78 | B33: F | C33: Analgesic | D33: 20 | E33: 88 | F33: 128 | G33: 15 | H33: No | I33: No | J33: No | K33: No | L33: 3 | M33: =IF($L33>17,"ICU","GMF") -> GMF | N33: GMF | Q33: Discharge | R33: Tylenol | S33: No | T33: No | U33: No | V33: Transfer to psych | W33: Confirmed -Yes | X33: Yes
A34: 131515-99 | B34: F | C34: Street Drugs | D34: 20 | E34: 71 | F34: 99 | G34: 15 | H34: No | I34: No | J34: No | K34: No | L34: 5 | M34: =IF($L34>17,"ICU","GMF") -> GMF | N34: GMF | Q34: Discharge | R34: fentanyl | S34: No | T34: No | U34: No | W34: Confirmed -Yes | X34: Yes
B35: F | C35: Analgesic | D35: 20 | E35: 74 | F35: 114 | G35: 15 | H35: No | I35: No | J35: No | K35: No | L35: 2 | M35: =IF($L35>17,"ICU","GMF") -> GMF | N35: GMF | Q35: Discharge | R35: 60 tablets of 220mg ibuprofen | S35: No | T35: No | U35: No | V35: Transfer to psych | W35: Confirmed -Yes | X35: Yes | AF35: Adults | AM35: Peds
A36: 131515-18 | B36: M | C36: Alcohol | D36: 21 | E36: 68 | F36: 126 | G36: 15 | H36: No | I36: No | J36: No | K36: No | L36: -5 | M36: =IF($L36>17,"ICU","GMF") -> GMF | N36: GMF | Q36: Discharge | S36: No | T36: No | W36: Unconfirmed | X36: Yes | AB36: MD | AI36: MD | AQ36: MD
B37: F | C37: Sedatives | D37: 22 | E37: 83 | F37: 110 | G37: 15 | H37: No | I37: No | J37: No | K37: No | L37: 1 | M37: =IF($L37>17,"ICU","GMF") -> GMF | N37: GMF | Q37: Discharge | R37: klonopin and benadryl | S37: No | T37: No | U37: No | V37: Transfer to psych | W37: Confirmed- No | X37: No | AB37: ICU | AC37: Not | AI37: ICU | AJ37: Not | AQ37: ICU | AR37: Not
B38: M | C38: Analgesic | D38: 24 | E38: 73 | F38: 131 | G38: 15 | H38: No | I38: No | J38: No | K38: No | L38: 0 | M38: =IF($L38>17,"ICU","GMF") -> GMF | N38: GMF | Q38: Discharge | R38: 5000mg advil within 6 hours | S38: No | T38: No | U38: No | W38: Confirmed- No | X38: No | Y38: ROC Optimized Threshold | Z38: Algo | AA38: ICU | AB38: =COUNTIFS($Q$2:$Q$120,"ICU",$M$2:$M$120,"ICU",$D$2:$D$120,">"&11) -> 8 | AC38: =COUNTIFS($Q$2:$Q$120,"<>ICU",$M$2:$M$120,"ICU",$D$2:$D$120,">"&11) -> 1 | AF38: ROC Optimized Threshold | AG38: Algo | AH38: ICU | AI38: =COUNTIFS($Q$2:$Q$120,"ICU",$M$2:$M$120,"ICU",$D$2:$D$120,">"&18) -> 7 | AJ38: =COUNTIFS($Q$2:$Q$120,"<>ICU",$M$2:$M$120,"ICU",$D$2:$D$120,">"&18) -> 1 | AM38: ROC Optimized Threshold | AO38: Algo | AP38: ICU | AQ38: =COUNTIFS($Q$2:$Q$120,"ICU",$M$2:$M$120,"ICU",$D$2:$D$120,">"&11, $D$2:$D$120,"<"&19) -> 1 | AR38: =COUNTIFS($Q$2:$Q$120,"<>ICU",$M$2:$M$120,"ICU",$D$2:$D$120,">"&11, $D$2:$D$120,"<"&19) -> 0
A39: 131515-92 | B39: F | C39: Unknown | D39: 26 | E39: 107 | F39: 118 | G39: 15 | H39: No | I39: No | J39: Yes | K39: No | L39: 14 | M39: =IF($L39>17,"ICU","GMF") -> GMF | N39: ICU | Q39: Discharge | R39: Early pregnancy injested unknown antibiotic and induced self vomiting | S39: No | T39: No | U39: No | V39: Transfer to psych | W39: Confirmed- No | X39: No | AA39: Not | AB39: =COUNTIFS($Q$2:$Q$120,"ICU",$M$2:$M$120,"<>ICU",$D$2:$D$120,">"&11) -> 12 | AC39: =COUNTIFS($Q$2:$Q$120,"<>ICU",$M$2:$M$120,"<>ICU",$D$2:$D$120,">"&11) -> 82 | AH39: Not | AI39: =COUNTIFS($Q$2:$Q$120,"ICU",$M$2:$M$120,"<>ICU",$D$2:$D$120,">"&8) -> 12 | AJ39: =COUNTIFS($Q$2:$Q$120,"<>ICU",$M$2:$M$120,"<>ICU",$D$2:$D$120,">"&18) -> 59 | AP39: Not | AQ39: =COUNTIFS($Q$2:$Q$120,"ICU",$M$2:$M$120,"<>ICU",$D$2:$D$120,">"&11, $D$2:$D$120,"<"&19) -> 3 | AR39: =COUNTIFS($Q$2:$Q$120,"<>ICU",$M$2:$M$120,"<>ICU",$D$2:$D$120,">"&11,$D$2:$D$120,"<"&19) -> 23
A40: 131515-1 | B40: F | C40: Alcohol | D40: 27 | E40: 97 | F40: 122 | G40: 15 | H40: No | I40: No | J40: No | K40: No | L40: 0 | M40: =IF($L40>17,"ICU","GMF") -> GMF | N40: GMF | Q40: Discharge | R40: Ethanol | S40: No | T40: No | W40: Confirmed -Yes | X40: Yes | AB40: SUM | AC40: =SUM(AB38:AC39) -> 103 | AE40: Kappa | AI40: SUM | AJ40: =SUM(AI38:AJ39) -> 79 | AQ40: SUM | AR40: =SUM(AQ38:AR39) -> 27
...

Sheet Dashboard
O1: Tox Etiology
O2: Y | P2: N
A3: Confirmed Exposure | B3: Yes | C3: No | D3: Unconfirmed | E3: N/A - WIthdrawal | F3: Fraction Complete | G3: SUM | I3: Exclusions | N3: Yes | O3: =COUNTIFS(INTOXICATE!W:W,INTOXICATE!$AB$3,INTOXICATE!X:X,INTOXICATE!$Y$2,INTOXICATE!D:D,">=12") -> 61 | P3: =COUNTIFS(INTOXICATE!W:W,INTOXICATE!$AB$3,INTOXICATE!X:X,INTOXICATE!$Y$3,INTOXICATE!D:D,">=12") -> 2 | Q3: =COUNTIFS(INTOXICATE!Y:Y,INTOXICATE!$AB$3,INTOXICATE!Z:Z,INTOXICATE!$Y$2) -> 0
B4: =COUNTIF(INTOXICATE!W:W,INTOXICATE!$AB$3) -> 67 | C4: =COUNTIF(INTOXICATE!W:W,INTOXICATE!$AB$4) -> 12 | D4: =COUNTIF(INTOXICATE!W:W,INTOXICATE!$AB$5) -> 31 | E4: =COUNTIF(INTOXICATE!W:W,INTOXICATE!$AB$6) -> 2 | F4: =COUNTA(INTOXICATE!$W$2:$W$114)/G4 -> 1 | G4: =SUM($B4:$E4) -> 112 | I4: Under 12 | J4: =COUNTIF(INTOXICATE!$D$2:$D$150,"<12") -> 9 | M4: Exposed | N4: No | O4: =COUNTIFS(INTOXICATE!W:W,INTOXICATE!$AB$4,INTOXICATE!X:X,INTOXICATE!$Y$2,INTOXICATE!D:D,">=12") -> 6 | P4: =COUNTIFS(INTOXICATE!W:W,INTOXICATE!$AB$4,INTOXICATE!X:X,INTOXICATE!$Y$3,INTOXICATE!D:D,">=12") -> 6 | Q4: =COUNTIFS(INTOXICATE!Y:Y,INTOXICATE!$AB$3,INTOXICATE!Z:Z,INTOXICATE!$Y$2) -> 0
A5: Incl in Analysis | B5: =COUNTIFS(INTOXICATE!W:W,INTOXICATE!$AB$3,INTOXICATE!D:D,">=12") -> 63 | C5: =COUNTIFS(INTOXICATE!W:W,INTOXICATE!$AB$4,INTOXICATE!D:D,">=12") -> 12 | D5: =COUNTIFS(INTOXICATE!W:W,INTOXICATE!$AB$5,INTOXICATE!D:D,">=12") -> 26 | E5: 0 | F5: =(COUNTA(INTOXICATE!$W$2:$W$114)-COUNTIF(INTOXICATE!D:D,"<=12"))/G5 -> 0.99009901 | G5: =SUM($B5:$D5) -> 101 | I5: Withdrawal | J5: =COUNTIFS(INTOXICATE!$D$2:$D$150,">11",INTOXICATE!$W$2:$W$150,INTOXICATE!$AB$6) -> 2 | N5: Maybe | O5: =COUNTIFS(INTOXICATE!W:W,INTOXICATE!$AB$5,INTOXICATE!X:X,INTOXICATE!$Y$2,INTOXICATE!D:D,">=12") -> 24 | P5: =COUNTIFS(INTOXICATE!W:W,INTOXICATE!$AB$5,INTOXICATE!X:X,INTOXICATE!$Y$3,INTOXICATE!D:D,">=12") -> 2
A6: Tox Etiology | B6: Yes | C6: No
B7: =COUNTIF(INTOXICATE!X2:X150,$B6) -> 101 | C7: =COUNTIF(INTOXICATE!Y2:Y150,$B6) -> 1 | F7: =COUNTA(INTOXICATE!$X$2:$X$113)/112 -> 1
A12: Age | B12: 25 | C12: 50 | D12: 75 | I12: Disposition | K12: Frac | L12: Adult | M12: Peds
A13: Adult | B13: {=QUARTILE(_xlfn._xlws.FILTER(INTOXICATE!$D$2:$D$150, (INTOXICATE!$D$2:$D$150>=18)*(INTOXICATE!$W$2:$W$150<>INTOXICATE!$AB$6)),1)} -> 27 | C13: {=QUARTILE(_xlfn._xlws.FILTER(INTOXICATE!$D$2:$D$150, (INTOXICATE!$D$2:$D$150>=18)*(INTOXICATE!$W$2:$W$150<>INTOXICATE!$AB$6)),2)} -> 35 | D13: {=QUARTILE(_xlfn._xlws.FILTER(INTOXICATE!$D$2:$D$150, (INTOXICATE!$D$2:$D$150>=18)*(INTOXICATE!$W$2:$W$150<>INTOXICATE!$AB$6)),3)} -> 50 | I13: ICU | J13: =COUNTIFS(INTOXICATE!$D$2:$D$150,">=12",INTOXICATE!$Q$2:$Q$150,$I13,INTOXICATE!$W$2:$W$150,"<>"&INTOXICATE!$AB$6) -> 19 | K13: =$J13/SUM($J$13:$J$15) -> 0.18811881 | L13: =COUNTIFS(INTOXICATE!$D$2:$D$150,">=12",INTOXICATE!$Q$2:$Q$150,$I13,INTOXICATE!$D$2:$D$150,">18",INTOXICATE!$W$2:$W$150,"<>"&INTOXICATE!$AB$6) -> 15 | M13: =COUNTIFS(INTOXICATE!$D$2:$D$150,">=12",INTOXICATE!$Q$2:$Q$150,$I13,INTOXICATE!$D$2:$D$150,"<18", INTOXICATE!$D$2:$D$150,">=12",INTOXICATE!$W$2:$W$150,"<>"&INTOXICATE!$AB$6) -> 4
A14: Peds | B14: {=QUARTILE(_xlfn._xlws.FILTER(INTOXICATE!$D$2:$D$150,(INTOXICATE!$D$2:$D$150<18)*(INTOXICATE!$D$2:$D$150>=12)*(INTOXICATE!$W$2:$W$150<>INTOXICATE!$AB$6)),1)} -> 14 | C14: {=QUARTILE(_xlfn._xlws.FILTER(INTOXICATE!$D$2:$D$150,(INTOXICATE!$D$2:$D$150<18)*(INTOXICATE!$D$2:$D$150>=12)*(INTOXICATE!$W$2:$W$150<>INTOXICATE!$AB$6)),2)} -> 15 | D14: {=QUARTILE(_xlfn._xlws.FILTER(INTOXICATE!$D$2:$D$150,(INTOXICATE!$D$2:$D$150<18)*(INTOXICATE!$D$2:$D$150>=12)*(INTOXICATE!$W$2:$W$150<>INTOXICATE!$AB$6)),3)} -> 16 | I14: GMF | J14: =COUNTIFS(INTOXICATE!$D$2:$D$150,">=12",INTOXICATE!$Q$2:$Q$150,$I14,INTOXICATE!$W$2:$W$150,"<>"&INTOXICATE!$AB$6) -> 16 | K14: =$J14/SUM($J$13:$J$15) -> 0.15841584 | L14: =COUNTIFS(INTOXICATE!$D$2:$D$150,">=12",INTOXICATE!$Q$2:$Q$150,$I14,INTOXICATE!$D$2:$D$150,">18",INTOXICATE!$W$2:$W$150,"<>"&INTOXICATE!$AB$6) -> 14 | M14: =COUNTIFS(INTOXICATE!$D$2:$D$150,">=12",INTOXICATE!$Q$2:$Q$150,$I14,INTOXICATE!$D$2:$D$150,"<18", INTOXICATE!$D$2:$D$150,">=12",INTOXICATE!$W$2:$W$150,"<>"&INTOXICATE!$AB$6) -> 2
I15: Discharge | J15: =COUNTIFS(INTOXICATE!$D$2:$D$150,">=12",INTOXICATE!$Q$2:$Q$150,$I15,INTOXICATE!$W$2:$W$150,"<>"&INTOXICATE!$AB$6) -> 66 | K15: =$J15/SUM($J$13:$J$15) -> 0.65346535 | L15: =COUNTIFS(INTOXICATE!$D$2:$D$150,">=12",INTOXICATE!$Q$2:$Q$150,$I15,INTOXICATE!$D$2:$D$150,">18",INTOXICATE!$W$2:$W$150,"<>"&INTOXICATE!$AB$6) -> 45 | M15: =COUNTIFS(INTOXICATE!$D$2:$D$150,">=12",INTOXICATE!$Q$2:$Q$150,$I15,INTOXICATE!$D$2:$D$150,"<18", INTOXICATE!$D$2:$D$150,">=12",INTOXICATE!$W$2:$W$150,"<>"&INTOXICATE!$AB$6) -> 18
A16: Gender | B16: M | C16: F | D16: NB
A17: Adult | B17: =COUNTIFS( INTOXICATE!$D$2:$D$150, ">=18", INTOXICATE!$W$2:$W$150, "<>"&INTOXICATE!$AB$6, INTOXICATE!$B$2:$B$150, B$16 ) -> 38 | C17: =COUNTIFS( INTOXICATE!$D$2:$D$150, ">=18", INTOXICATE!$W$2:$W$150, "<>"&INTOXICATE!$AB$6, INTOXICATE!$B$2:$B$150, C$16 ) -> 39 | D17: =COUNTIFS( INTOXICATE!$D$2:$D$150, ">=18", INTOXICATE!$W$2:$W$150, "<>"&INTOXICATE!$AB$6, INTOXICATE!$B$2:$B$150, D$16 ) -> 0 | P17: Higher Threshold
A18: Peds | B18: =COUNTIFS( INTOXICATE!$D$2:$D$150, "<18", INTOXICATE!$W$2:$W$150, "<>"&INTOXICATE!$AB$6, INTOXICATE!$B$2:$B$150, B$16, INTOXICATE!$D$2:$D$150,">=12" ) -> 10 | C18: =COUNTIFS( INTOXICATE!$D$2:$D$150, "<18", INTOXICATE!$W$2:$W$150, "<>"&INTOXICATE!$AB$6, INTOXICATE!$B$2:$B$150, C$16, INTOXICATE!$D$2:$D$150,">=12" ) -> 13 | D18: =COUNTIFS( INTOXICATE!$D$2:$D$150, "<18", INTOXICATE!$W$2:$W$150, "<>"&INTOXICATE!$AB$6, INTOXICATE!$B$2:$B$150, D$16, INTOXICATE!$D$2:$D$150,">=12" ) -> 1 | J18: Overall | Q18: Overall
J19: Actual | Q19: Actual
A20: SBP | I20: ICU | J20: GMF | K20: Discharge | P20: ICU | Q20: GMF | R20: Discharge
A21: Adult | B21: {=QUARTILE(_xlfn._xlws.FILTER(INTOXICATE!$F$2:$F$150, (INTOXICATE!$D$2:$D$150>=18)*(INTOXICATE!$W$2:$W$150<>INTOXICATE!$AB$6)),1)} -> 112 | C21: {=QUARTILE(_xlfn._xlws.FILTER(INTOXICATE!$F$2:$F$150, (INTOXICATE!$D$2:$D$150>=18)*(INTOXICATE!$W$2:$W$150<>INTOXICATE!$AB$6)),2)} -> 120 | D21: {=QUARTILE(_xlfn._xlws.FILTER(INTOXICATE!$F$2:$F$150, (INTOXICATE!$D$2:$D$150>=18)*(INTOXICATE!$W$2:$W$150<>INTOXICATE!$AB$6)),3)} -> 139 | H21: GMF | I21: =COUNTIFS(INTOXICATE!$W$2:$W$114,"<>"&INTOXICATE!$AB$6,INTOXICATE!$D$2:$D$114,">=12",INTOXICATE!$N$2:$N$114,$H21,INTOXICATE!$Q$2:$Q$114,I$20) -> 6 | J21: =COUNTIFS(INTOXICATE!$W$2:$W$114,"<>"&INTOXICATE!$AB$6,INTOXICATE!$D$2:$D$114,">=12",INTOXICATE!$N$2:$N$114,$H21, INTOXICATE!$Q$2:$Q$114,J$20) -> 4 | K21: =COUNTIFS(INTOXICATE!$W$2:$W$114,"<>"&INTOXICATE!$AB$6,INTOXICATE!$D$2:$D$114,">=12",INTOXICATE!$N$2:$N$114,$H21, INTOXICATE!$Q$2:$Q$114,K$20) -> 30 | O21: GMF | P21: =COUNTIFS(INTOXICATE!$W$2:$W$114,"<>"&INTOXICATE!$AB$6,INTOXICATE!$D$2:$D$114,">=12",INTOXICATE!$M$2:$M$114,$H21,INTOXICATE!$Q$2:$Q$114,P$20) -> 11 | Q21: =COUNTIFS(INTOXICATE!$W$2:$W$114,"<>"&INTOXICATE!$AB$6,INTOXICATE!$D$2:$D$114,">=12",INTOXICATE!$M$2:$M$114,$H21,INTOXICATE!$Q$2:$Q$114,Q$20) -> 15 | R21: =COUNTIFS(INTOXICATE!$W$2:$W$114,"<>"&INTOXICATE!$AB$6,INTOXICATE!$D$2:$D$114,">=12",INTOXICATE!$M$2:$M$114,$H21,INTOXICATE!$Q$2:$Q$114,R$20) -> 66
A22: Peds | B22: {=QUARTILE(_xlfn._xlws.FILTER(INTOXICATE!$F$2:$F$150,(INTOXICATE!$D$2:$D$150<18)*(INTOXICATE!$D$2:$D$150>=12)*(INTOXICATE!$W$2:$W$150<>INTOXICATE!$AB$6)),1)} -> 105.75 | C22: {=QUARTILE(_xlfn._xlws.FILTER(INTOXICATE!$F$2:$F$150,(INTOXICATE!$D$2:$D$150<18)*(INTOXICATE!$D$2:$D$150>=12)*(INTOXICATE!$W$2:$W$150<>INTOXICATE!$AB$6)),2)} -> 116 | D22: {=QUARTILE(_xlfn._xlws.FILTER(INTOXICATE!$F$2:$F$150,(INTOXICATE!$D$2:$D$150<18)*(INTOXICATE!$D$2:$D$150>=12)*(INTOXICATE!$W$2:$W$150<>INTOXICATE!$AB$6)),3)} -> 119.25 | G22: INTOXICATE | H22: ICU | I22: =COUNTIFS(INTOXICATE!$W$2:$W$114,"<>"&INTOXICATE!$AB$6,INTOXICATE!$D$2:$D$114,">=12",INTOXICATE!$N$2:$N$114,$H22,INTOXICATE!$Q$2:$Q$114,I$20) -> 13 | J22: =COUNTIFS(INTOXICATE!$W$2:$W$114,"<>"&INTOXICATE!$AB$6,INTOXICATE!$D$2:$D$114,">=12",INTOXICATE!$N$2:$N$114,$H22, INTOXICATE!$Q$2:$Q$114,J$20) -> 12 | K22: =COUNTIFS(INTOXICATE!$W$2:$W$114,"<>"&INTOXICATE!$AB$6,INTOXICATE!$D$2:$D$114,">=12",INTOXICATE!$N$2:$N$114,$H22, INTOXICATE!$Q$2:$Q$114,K$20) -> 36 | N22: INTOXICATE | O22: ICU | P22: =COUNTIFS(INTOXICATE!$W$2:$W$114,"<>"&INTOXICATE!$AB$6,INTOXICATE!$D$2:$D$114,">=12",INTOXICATE!$M$2:$M$114,$H22,INTOXICATE!$Q$2:$Q$114,P$20) -> 8 | Q22: =COUNTIFS(INTOXICATE!$W$2:$W$114,"<>"&INTOXICATE!$AB$6,INTOXICATE!$D$2:$D$114,">=12",INTOXICATE!$M$2:$M$114,$H22,INTOXICATE!$Q$2:$Q$114,Q$20) -> 1 | R22: =COUNTIFS(INTOXICATE!$W$2:$W$114,"<>"&INTOXICATE!$AB$6,INTOXICATE!$D$2:$D$114,">=12",INTOXICATE!$M$2:$M$114,$H22,INTOXICATE!$Q$2:$Q$114,R$20) -> 0
A24: Pulse | L24: =39/77 -> 0.50649351
A25: Adult | B25: {=QUARTILE(_xlfn._xlws.FILTER(INTOXICATE!$E$2:$E$150, (INTOXICATE!$D$2:$D$150>=18)*(INTOXICATE!$W$2:$W$150<>INTOXICATE!$AB$6)),1)} -> 71 | C25: {=QUARTILE(_xlfn._xlws.FILTER(INTOXICATE!$E$2:$E$150, (INTOXICATE!$D$2:$D$150>=18)*(INTOXICATE!$W$2:$W$150<>INTOXICATE!$AB$6)),2)} -> 90 | D25: {=QUARTILE(_xlfn._xlws.FILTER(INTOXICATE!$E$2:$E$150, (INTOXICATE!$D$2:$D$150>=18)*(INTOXICATE!$W$2:$W$150<>INTOXICATE!$AB$6)),3)} -> 106 | J25: Peds | Q25: Peds
A26: Peds | B26: {=QUARTILE(_xlfn._xlws.FILTER(INTOXICATE!$E$2:$E$150,(INTOXICATE!$D$2:$D$150<18)*(INTOXICATE!$D$2:$D$150>=12)*(INTOXICATE!$W$2:$W$150<>INTOXICATE!$AB$6)),1)} -> 88.75 | C26: {=QUARTILE(_xlfn._xlws.FILTER(INTOXICATE!$E$2:$E$150,(INTOXICATE!$D$2:$D$150<18)*(INTOXICATE!$D$2:$D$150>=12)*(INTOXICATE!$W$2:$W$150<>INTOXICATE!$AB$6)),2)} -> 99 | D26: {=QUARTILE(_xlfn._xlws.FILTER(INTOXICATE!$E$2:$E$150,(INTOXICATE!$D$2:$D$150<18)*(INTOXICATE!$D$2:$D$150>=12)*(INTOXICATE!$W$2:$W$150<>INTOXICATE!$AB$6)),3)} -> 110.25 | J26: Actual | Q26: Actual
I27: ICU | J27: GMF | K27: Discharge | P27: ICU | Q27: GMF | R27: Discharge
A28: 2ary Reasons | H28: GMF | I28: =COUNTIFS(INTOXICATE!$W$2:$W$114,"<>"&INTOXICATE!$AB$6,INTOXICATE!$D$2:$D$114,">=12",INTOXICATE!$N$2:$N$114,$H28,INTOXICATE!$Q$2:$Q$114,I$20,INTOXICATE!$D$2:$D$114,"<18") -> 2 | J28: =COUNTIFS(INTOXICATE!$W$2:$W$114,"<>"&INTOXICATE!$AB$6,INTOXICATE!$D$2:$D$114,">=12",INTOXICATE!$N$2:$N$114,$H28,INTOXICATE!$Q$2:$Q$114,J$20,INTOXICATE!$D$2:$D$114,"<18") -> 2 | K28: =COUNTIFS(INTOXICATE!$W$2:$W$114,"<>"&INTOXICATE!$AB$6,INTOXICATE!$D$2:$D$114,">=12",INTOXICATE!$N$2:$N$114,$H28,INTOXICATE!$Q$2:$Q$114,K$20,INTOXICATE!$D$2:$D$114,"<18") -> 9 | O28: GMF | P28: =COUNTIFS(INTOXICATE!$W$2:$W$114,"<>"&INTOXICATE!$AB$6,INTOXICATE!$D$2:$D$114,">=12",INTOXICATE!$M$2:$M$114,$H28,INTOXICATE!$Q$2:$Q$114,P$20,INTOXICATE!$D$2:$D$114,"<18") -> 3 | Q28: =COUNTIFS(INTOXICATE!$W$2:$W$114,"<>"&INTOXICATE!$AB$6,INTOXICATE!$D$2:$D$114,">=12",INTOXICATE!$M$2:$M$114,$H28,INTOXICATE!$Q$2:$Q$114,Q$20,INTOXICATE!$D$2:$D$114,"<18") -> 2 | R28: =COUNTIFS(INTOXICATE!$W$2:$W$114,"<>"&INTOXICATE!$AB$6,INTOXICATE!$D$2:$D$114,">=12",INTOXICATE!$M$2:$M$114,$H28,INTOXICATE!$Q$2:$Q$114,R$20,INTOXICATE!$D$2:$D$114,"<18") -> 18
A29: Resp | B29: =COUNTIFS( INTOXICATE!$D$2:$D$150, ">=18", INTOXICATE!$W$2:$W$150, "<>"&INTOXICATE!$AB$6, INTOXICATE!$H$2:$H$150, "Yes" ) -> 16 | C29: =COUNTIFS( INTOXICATE!$D$2:$D$150, "<18", INTOXICATE!$D$2:$D$150,">=12", INTOXICATE!$W$2:$W$150, "<>"&INTOXICATE!$AB$6, INTOXICATE!$H$2:$H$150, "Yes" ) -> 2 | G29: INTOXICATE | H29: ICU | I29: =COUNTIFS(INTOXICATE!$W$2:$W$114,"<>"&INTOXICATE!$AB$6,INTOXICATE!$D$2:$D$114,">=12",INTOXICATE!$N$2:$N$114,$H29,INTOXICATE!$Q$2:$Q$114,I$20,INTOXICATE!$D$2:$D$114,"<18") -> 2 | J29: =COUNTIFS(INTOXICATE!$W$2:$W$114,"<>"&INTOXICATE!$AB$6,INTOXICATE!$D$2:$D$114,">=12",INTOXICATE!$N$2:$N$114,$H29,INTOXICATE!$Q$2:$Q$114,J$20,INTOXICATE!$D$2:$D$114,"<18") -> 0 | K29: =COUNTIFS(INTOXICATE!$W$2:$W$114,"<>"&INTOXICATE!$AB$6,INTOXICATE!$D$2:$D$114,">=12",INTOXICATE!$N$2:$N$114,$H29,INTOXICATE!$Q$2:$Q$114,K$20,INTOXICATE!$D$2:$D$114,"<18") -> 9 | N29: INTOXICATE | O29: ICU | P29: =COUNTIFS(INTOXICATE!$W$2:$W$114,"<>"&INTOXICATE!$AB$6,INTOXICATE!$D$2:$D$114,">=12",INTOXICATE!$M$2:$M$114,$H29,INTOXICATE!$Q$2:$Q$114,P$20,INTOXICATE!$D$2:$D$114,"<18") -> 1 | Q29: =COUNTIFS(INTOXICATE!$W$2:$W$114,"<>"&INTOXICATE!$AB$6,INTOXICATE!$D$2:$D$114,">=12",INTOXICATE!$M$2:$M$114,$H29,INTOXICATE!$Q$2:$Q$114,Q$20,INTOXICATE!$D$2:$D$114,"<18") -> 0 | R29: =COUNTIFS(INTOXICATE!$W$2:$W$114,"<>"&INTOXICATE!$AB$6,INTOXICATE!$D$2:$D$114,">=12",INTOXICATE!$M$2:$M$114,$H29,INTOXICATE!$Q$2:$Q$114,R$20,INTOXICATE!$D$2:$D$114,"<18") -> 0
A30: Cirrhosis | B30: =COUNTIFS( INTOXICATE!$D$2:$D$150, ">=18", INTOXICATE!$W$2:$W$150, "<>"&INTOXICATE!$AB$6, INTOXICATE!$I$2:$I$150, "Yes" ) -> 2 | C30: =COUNTIFS( INTOXICATE!$D$2:$D$150, "<18", INTOXICATE!$D$2:$D$150,">=12", INTOXICATE!$W$2:$W$150, "<>"&INTOXICATE!$AB$6, INTOXICATE!$I$2:$I$150, "Yes" ) -> 0
A31: Dysrhythmia | B31: =COUNTIFS( INTOXICATE!$D$2:$D$150, ">=18", INTOXICATE!$W$2:$W$150, "<>"&INTOXICATE!$AB$6, INTOXICATE!$J$2:$J$150, "Yes" ) -> 28 | C31: =COUNTIFS( INTOXICATE!$D$2:$D$150, "<18", INTOXICATE!$D$2:$D$150,">=12", INTOXICATE!$W$2:$W$150, "<>"&INTOXICATE!$AB$6, INTOXICATE!$J$2:$J$150, "Yes" ) -> 12 | J31: Adult | Q31: Adult
A32: Other | B32: =COUNTIFS( INTOXICATE!$D$2:$D$150, ">=18", INTOXICATE!$W$2:$W$150, "<>"&INTOXICATE!$AB$6, INTOXICATE!$K$2:$K$150, "Yes" ) -> 1 | C32: =COUNTIFS( INTOXICATE!$D$2:$D$150, "<18", INTOXICATE!$D$2:$D$150,">=12", INTOXICATE!$W$2:$W$150, "<>"&INTOXICATE!$AB$6, INTOXICATE!$K$2:$K$150, "Yes" ) -> 0 | J32: Actual | Q32: Actual
B33: Adult | C33: Peds | I33: ICU | J33: GMF | K33: Discharge | P33: ICU | Q33: GMF | R33: Discharge
H34: GMF | I34: =COUNTIFS(INTOXICATE!$W$2:$W$114,"<>"&INTOXICATE!$AB$6,INTOXICATE!$D$2:$D$114,">=12",INTOXICATE!$N$2:$N$114,$H34,INTOXICATE!$Q$2:$Q$114,I$20,INTOXICATE!$D$2:$D$114,">18") -> 4 | J34: =COUNTIFS(INTOXICATE!$W$2:$W$114,"<>"&INTOXICATE!$AB$6,INTOXICATE!$D$2:$D$114,">=12",INTOXICATE!$N$2:$N$114,$H34,INTOXICATE!$Q$2:$Q$114,J$20,INTOXICATE!$D$2:$D$114,">18") -> 2 | K34: =COUNTIFS(INTOXICATE!$W$2:$W$114,"<>"&INTOXICATE!$AB$6, INTOXICATE!$D$2:$D$114,">=12", INTOXICATE!$N$2:$N$114,$H34, INTOXICATE!$Q$2:$Q$114,K$20, INTOXICATE!$D$2:$D$114,">18") -> 19 | O34: GMF | P34: =COUNTIFS(INTOXICATE!$W$2:$W$114,"<>"&INTOXICATE!$AB$6,INTOXICATE!$D$2:$D$114,">=12",INTOXICATE!$M$2:$M$114,$H34,INTOXICATE!$Q$2:$Q$114,P$20,INTOXICATE!$D$2:$D$114,">18") -> 8 | Q34: =COUNTIFS(INTOXICATE!$W$2:$W$114,"<>"&INTOXICATE!$AB$6,INTOXICATE!$D$2:$D$114,">=12",INTOXICATE!$M$2:$M$114,$H34,INTOXICATE!$Q$2:$Q$114,Q$20,INTOXICATE!$D$2:$D$114,">18") -> 13 | R34: =COUNTIFS(INTOXICATE!$W$2:$W$114,"<>"&INTOXICATE!$AB$6,INTOXICATE!$D$2:$D$114,">=12",INTOXICATE!$M$2:$M$114,$H34,INTOXICATE!$Q$2:$Q$114,R$20,INTOXICATE!$D$2:$D$114,">18") -> 45
A35: GCS | G35: INTOXICATE | H35: ICU | I35: =COUNTIFS(INTOXICATE!$W$2:$W$114,"<>"&INTOXICATE!$AB$6,INTOXICATE!$D$2:$D$114,">=12",INTOXICATE!$N$2:$N$114,$H35,INTOXICATE!$Q$2:$Q$114,I$20,INTOXICATE!$D$2:$D$114,">18") -> 11 | J35: =COUNTIFS(INTOXICATE!$W$2:$W$114,"<>"&INTOXICATE!$AB$6,INTOXICATE!$D$2:$D$114,">=12",INTOXICATE!$N$2:$N$114,$H35,INTOXICATE!$Q$2:$Q$114,J$20,INTOXICATE!$D$2:$D$114,">18") -> 12 | K35: =COUNTIFS(INTOXICATE!$W$2:$W$114,"<>"&INTOXICATE!$AB$6, INTOXICATE!$D$2:$D$114,">=12", INTOXICATE!$N$2:$N$114,$H35, INTOXICATE!$Q$2:$Q$114,K$20, INTOXICATE!$D$2:$D$114,">18") -> 26 | N35: INTOXICATE | O35: ICU | P35: =COUNTIFS(INTOXICATE!$W$2:$W$114,"<>"&INTOXICATE!$AB$6,INTOXICATE!$D$2:$D$114,">=12",INTOXICATE!$M$2:$M$114,$H35,INTOXICATE!$Q$2:$Q$114,P$20,INTOXICATE!$D$2:$D$114,">18") -> 7 | Q35: =COUNTIFS(INTOXICATE!$W$2:$W$114,"<>"&INTOXICATE!$AB$6,INTOXICATE!$D$2:$D$114,">=12",INTOXICATE!$M$2:$M$114,$H35,INTOXICATE!$Q$2:$Q$114,Q$20,INTOXICATE!$D$2:$D$114,">18") -> 1 | R35: =COUNTIFS(INTOXICATE!$W$2:$W$114,"<>"&INTOXICATE!$AB$6,INTOXICATE!$D$2:$D$114,">=12",INTOXICATE!$M$2:$M$114,$H35,INTOXICATE!$Q$2:$Q$114,R$20,INTOXICATE!$D$2:$D$114,">18") -> 0
A36: 3 | B36: =COUNTIFS( INTOXICATE!$D$2:$D$150, ">=18", INTOXICATE!$W$2:$W$150, "<>"&INTOXICATE!$AB$6, INTOXICATE!$G$2:$G$150, $A36 ) -> 3 | C36: =COUNTIFS( INTOXICATE!$D$2:$D$150, "<18", INTOXICATE!$D$2:$D$150, ">=12", INTOXICATE!$W$2:$W$150, "<>"&INTOXICATE!$AB$6, INTOXICATE!$G$2:$G$150, $A36 ) -> 0 | I36: =SUM(I34:I35) -> 15 | J36: =SUM(J34:J35) -> 14 | K36: =SUM(K34:K35) -> 45 | P36: =SUM(P34:P35) -> 15 | Q36: =SUM(Q34:Q35) -> 14 | R36: =SUM(R34:R35) -> 45
A37: 5 | B37: =COUNTIFS( INTOXICATE!$D$2:$D$150, ">=18", INTOXICATE!$W$2:$W$150, "<>"&INTOXICATE!$AB$6, INTOXICATE!$G$2:$G$150, $A37 ) -> 1 | C37: =COUNTIFS( INTOXICATE!$D$2:$D$150, "<18", INTOXICATE!$D$2:$D$150, ">=12", INTOXICATE!$W$2:$W$150, "<>"&INTOXICATE!$AB$6, INTOXICATE!$G$2:$G$150, $A37 ) -> 0 | I37: =I36/SUM($I$36:$K$36) -> 0.2027027 | J37: =J36/SUM($I$36:$K$36) -> 0.18918919 | K37: =K36/SUM($I$36:$K$36) -> 0.60810811
A38: 10 | B38: =COUNTIFS( INTOXICATE!$D$2:$D$150, ">=18", INTOXICATE!$W$2:$W$150, "<>"&INTOXICATE!$AB$6, INTOXICATE!$G$2:$G$150, $A38 ) -> 0 | C38: =COUNTIFS( INTOXICATE!$D$2:$D$150, "<18", INTOXICATE!$D$2:$D$150, ">=12", INTOXICATE!$W$2:$W$150, "<>"&INTOXICATE!$AB$6, INTOXICATE!$G$2:$G$150, $A38 ) -> 3
A39: 11 | B39: =COUNTIFS( INTOXICATE!$D$2:$D$150, ">=18", INTOXICATE!$W$2:$W$150, "<>"&INTOXICATE!$AB$6, INTOXICATE!$G$2:$G$150, $A39 ) -> 1 | C39: =COUNTIFS( INTOXICATE!$D$2:$D$150, "<18", INTOXICATE!$D$2:$D$150, ">=12", INTOXICATE!$W$2:$W$150, "<>"&INTOXICATE!$AB$6, INTOXICATE!$G$2:$G$150, $A39 ) -> 0
A40: 12 | B40: =COUNTIFS( INTOXICATE!$D$2:$D$150, ">=18", INTOXICATE!$W$2:$W$150, "<>"&INTOXICATE!$AB$6, INTOXICATE!$G$2:$G$150, $A40 ) -> 1 | C40: =COUNTIFS( INTOXICATE!$D$2:$D$150, "<18", INTOXICATE!$D$2:$D$150, ">=12", INTOXICATE!$W$2:$W$150, "<>"&INTOXICATE!$AB$6, INTOXICATE!$G$2:$G$150, $A40 ) -> 0
A41: 13 | B41: =COUNTIFS( INTOXICATE!$D$2:$D$150, ">=18", INTOXICATE!$W$2:$W$150, "<>"&INTOXICATE!$AB$6, INTOXICATE!$G$2:$G$150, $A41 ) -> 2 | C41: =COUNTIFS( INTOXICATE!$D$2:$D$150, "<18", INTOXICATE!$D$2:$D$150, ">=12", INTOXICATE!$W$2:$W$150, "<>"&INTOXICATE!$AB$6, INTOXICATE!$G$2:$G$150, $A41 ) -> 0
A42: 14 | B42: =COUNTIFS( INTOXICATE!$D$2:$D$150, ">=18", INTOXICATE!$W$2:$W$150, "<>"&INTOXICATE!$AB$6, INTOXICATE!$G$2:$G$150, $A42 ) -> 2 | C42: =COUNTIFS( INTOXICATE!$D$2:$D$150, "<18", INTOXICATE!$D$2:$D$150, ">=12", INTOXICATE!$W$2:$W$150, "<>"&INTOXICATE!$AB$6, INTOXICATE!$G$2:$G$150, $A42 ) -> 3 | G42: Needed ICU | I42: Tox | K42: INTOXICATE
A43: 15 | B43: =COUNTIFS( INTOXICATE!$D$2:$D$150, ">=18", INTOXICATE!$W$2:$W$150, "<>"&INTOXICATE!$AB$6, INTOXICATE!$G$2:$G$150, $A43 ) -> 67 | C43: =COUNTIFS( INTOXICATE!$D$2:$D$150, "<18", INTOXICATE!$D$2:$D$150, ">=12", INTOXICATE!$W$2:$W$150, "<>"&INTOXICATE!$AB$6, INTOXICATE!$G$2:$G$150, $A43 ) -> 18 | H43: Yes | I43: No | K43: Yes | L43: No
G44: Yes | H44: =COUNTIFS(INTOXICATE!$Q$2:$Q$115,"ICU",INTOXICATE!$U$2:$U$115,$G44) -> 11 | I44: =COUNTIFS(INTOXICATE!$Q$2:$Q$115,"<>ICU",INTOXICATE!$U$2:$U$115,$G44) -> 1 | K44: =COUNTIFS(INTOXICATE!$M$2:$M$115,"ICU",INTOXICATE!$U$2:$U$115,$G44) -> 7 | L44: =COUNTIFS(INTOXICATE!$M$2:$M$115,"<>ICU",INTOXICATE!$U$2:$U$115,$G44) -> 5
A45: Exposure Categories | G45: No | H45: =COUNTIFS(INTOXICATE!$Q$2:$Q$115,"ICU",INTOXICATE!$U$2:$U$115,$G45) -> 3 | I45: =COUNTIFS(INTOXICATE!$Q$2:$Q$115,"<>ICU",INTOXICATE!$U$2:$U$115,$G45) -> 81 | K45: =COUNTIFS(INTOXICATE!$M$2:$M$115,"ICU",INTOXICATE!$U$2:$U$115,$G45) -> 2 | L45: =COUNTIFS(INTOXICATE!$M$2:$M$115,"<>ICU",INTOXICATE!$U$2:$U$115,$G45) -> 82
...

Sheet Smartsheet not in report
A1: DOS | B1: Name | C1: MRN | D1: Notes
A2: 45026 | B2: Azamat Kutlukov | C2: 1205351623 | D2: Dr. Rao "progress note" Inpatient consult to toxicology CON67 in referrals but "order status" says canceled
A3: 45026 | B3: Aurelian Asad | C3: 1400844846 | D3: Dr. Rao "progress note" Inpatient consult to toxicology CON67 in referrals but "order status" says canceled
A4: 45027 | B4: Brianna Olamiju | C4: 1100584785 | D4: Dr. Rao "progress note" Inpatient consult to toxicology CON67 in referrals but "order status" says canceled
A5: 45027 | B5: Sharlyn Singh | C5: 1401175674 | D5: Dr. Rao "consult" Inpatient consult to toxicology CON67 in referrals Completed consult to toxicology in Orders
A6: 45027 | B6: Alexander Gottdiener | C6: 1007731399
A7: 45027 | B7: Constance Desena | C7: 1401178427
A8: 45028 | B8: Vicki Stafford | C8: 1000422530
A9: 45028 | B9: Kupferstein Nusy | C9: 1203455978
A10: 45028 | B10: Emilia Saysette | C10: 1401179331
A11: 45028 | B11: Barbara P Parker | C11: 1008038019
A12: 45030 | B12: Samantha Philips | C12: 1102776593
A13: 45031 | B13: Gemma Stanger | C13: 1401183624
A14: 45033 | B14: Archea Hyacinthe | C14: 1006922086 | D14: (note this is a different MRN than Smartsheet, the one listed there does not pull up any patient records)
A15: 45034 | B15: Jeffrey Slater | C15: 1007133642
A16: 45034 | B16: Solmaria Hernandez | C16: 1007930850
A17: 45037 | B17: Narine Budram | C17: 1401187351
A18: 45038 | B18: Matthew Heras Galaby | C18: 1201324361
A19: 45039 | B19: Kasey Chatterji | C19: 1400432623 | D19: Dr. Rao "progress note" Inpatient consult to toxicology CON67 in referrals but "order status" says canceled
A20: 45039 | B20: Narda Mendez | C20: 1000565302 | D20: Dr. Rao "consult" Inpatient consult to toxicology CON67 in referrals but "order status" says canceled
A21: 45045 | B21: Anthony Locascio | C21: 1203280315 | D21: Dr. Rao "progress note" Inpatient consult to toxicology CON67 in referrals but "order status" says canceled
A22: 45045 | B22: Jonathan Zahavi | C22: 1010356971 | D22: Dr. Rao "progress note" Inpatient consult to toxicology CON67 in referrals but "order status" says canceled
A23: 45046 | B23: Georgevich Bogdan | C23: 1101654813 | D23: Dr. Rao "progress note" Inpatient consult to toxicology CON67 in referrals but "order status" says canceled
A24: 45046 | B24: Scarlett Beckman | C24: 1401201782 | D24: Dr. Rao "progress note" Inpatient consult to toxicology CON67 in referrals but "order status" says canceled
A25: 45047 | B25: Seanna Elliott | C25: 1006067284 | D25: Dr. Rao "progress note" No referral or consult orders in chart under encounters this is listed as a standalone "E-Consult"
A26: 45049 | B26: Yisroel Armel | C26: 1401011614 | D26: no tox note however there is a referral with a canceled order status
A27: 45051 | B27: Ana Santiago | C27: 1010489188 | D27: no tox note or referral for this patient - Dr. Rao was the incoming attending for the patient
A28: 45052 | B28: Kaden V Salley | C28: 1400316000 | D28: Dr. Rao "progress note" Inpatient consult to toxicology CON67 in referrals but "order status" says canceled
A29: 45053 | B29: Catherine Chin | C29: 1400163746 | D29: Dr. Rao "progress note" Inpatient consult to toxicology CON67 in referrals but "order status" says canceled
A30: 45071 | B30: Osyrus Gonzalez | C30: 1401210629 | D30: Dr. Rao "progress note" Inpatient consult to toxicology CON67 in referrals but "order status" says canceled
... A42: 45111 | B42: Kendall Gonzalez | C42: 1203195479 | D42: Dr. Rao "Consult" Inpatient consult to toxicology CON67 in referrals but "order status" says canceled
